2021-11-09 23:08:16,088 INFO    MainThread:1136803 [wandb_setup.py:_flush():71] setting env: {}
2021-11-09 23:08:16,088 INFO    MainThread:1136803 [wandb_setup.py:_flush():71] setting login settings: {}
2021-11-09 23:08:16,088 INFO    MainThread:1136803 [wandb_init.py:_log_setup():357] Logging user logs to /media/indika/Sync/Programming/Projects/Python/Artifical-Intelligence/PyTorch/RNN/Gooogle-Stock-Price-V6/wandb/run-20211109_230816-2wsa7t2c/logs/debug.log
2021-11-09 23:08:16,088 INFO    MainThread:1136803 [wandb_init.py:_log_setup():358] Logging internal logs to /media/indika/Sync/Programming/Projects/Python/Artifical-Intelligence/PyTorch/RNN/Gooogle-Stock-Price-V6/wandb/run-20211109_230816-2wsa7t2c/logs/debug-internal.log
2021-11-09 23:08:16,088 INFO    MainThread:1136803 [wandb_init.py:_jupyter_setup():307] configuring jupyter hooks <wandb.sdk.wandb_init._WandbInit object at 0x7f77b9bbd160>
2021-11-09 23:08:16,088 INFO    MainThread:1136803 [wandb_init.py:init():390] calling init triggers
2021-11-09 23:08:16,088 INFO    MainThread:1136803 [wandb_init.py:init():395] wandb.init called with sweep_config: {}
config: {}
2021-11-09 23:08:16,088 INFO    MainThread:1136803 [wandb_init.py:init():435] starting backend
2021-11-09 23:08:16,088 INFO    MainThread:1136803 [backend.py:_multiprocessing_setup():94] multiprocessing start_methods=fork,spawn,forkserver, using: spawn
2021-11-09 23:08:16,129 INFO    MainThread:1136803 [backend.py:ensure_launched():198] starting backend process...
2021-11-09 23:08:16,132 ERROR   Thread-4  :1136803 [internal_api.py:execute():144] 500 response executing GraphQL.
2021-11-09 23:08:16,133 ERROR   Thread-4  :1136803 [internal_api.py:execute():145] {"error":"Error 1040: Too many connections"}

2021-11-09 23:08:16,133 ERROR   Thread-4  :1136803 [retry.py:__call__():126] Retry attempt failed:
Traceback (most recent call last):
  File "/media/indika/Sync/anaconda3/lib/python3.8/site-packages/wandb/sdk/lib/retry.py", line 102, in __call__
    result = self._call_fn(*args, **kwargs)
  File "/media/indika/Sync/anaconda3/lib/python3.8/site-packages/wandb/sdk/internal/internal_api.py", line 147, in execute
    six.reraise(*sys.exc_info())
  File "/home/indika/.local/lib/python3.8/site-packages/six.py", line 719, in reraise
    raise value
  File "/media/indika/Sync/anaconda3/lib/python3.8/site-packages/wandb/sdk/internal/internal_api.py", line 141, in execute
    return self.client.execute(*args, **kwargs)
  File "/media/indika/Sync/anaconda3/lib/python3.8/site-packages/wandb/vendor/gql-0.2.0/gql/client.py", line 52, in execute
    result = self._get_result(document, *args, **kwargs)
  File "/media/indika/Sync/anaconda3/lib/python3.8/site-packages/wandb/vendor/gql-0.2.0/gql/client.py", line 60, in _get_result
    return self.transport.execute(document, *args, **kwargs)
  File "/media/indika/Sync/anaconda3/lib/python3.8/site-packages/wandb/vendor/gql-0.2.0/gql/transport/requests.py", line 39, in execute
    request.raise_for_status()
  File "/home/indika/.local/lib/python3.8/site-packages/requests/models.py", line 953, in raise_for_status
    raise HTTPError(http_error_msg, response=self)
requests.exceptions.HTTPError: 500 Server Error: Internal Server Error for url: https://api.wandb.ai/graphql
2021-11-09 23:08:16,171 INFO    MainThread:1136803 [backend.py:ensure_launched():203] started backend process with pid: 1137159
2021-11-09 23:08:16,175 INFO    MainThread:1136803 [wandb_init.py:init():444] backend started and connected
2021-11-09 23:08:16,191 INFO    MainThread:1136803 [wandb_run.py:_label_probe_notebook():866] probe notebook
2021-11-09 23:08:16,193 INFO    MainThread:1136803 [wandb_init.py:init():503] updated telemetry
2021-11-09 23:08:16,195 INFO    MainThread:1136803 [wandb_init.py:init():533] communicating current version
2021-11-09 23:08:17,259 INFO    MainThread:1136803 [wandb_init.py:init():538] got version response upgrade_message: "wandb version 0.12.6 is available!  To upgrade, please run:\n $ pip install wandb --upgrade"

2021-11-09 23:08:17,260 INFO    MainThread:1136803 [wandb_init.py:init():548] communicating run to backend with 30 second timeout
2021-11-09 23:08:21,134 ERROR   Thread-4  :1136803 [internal_api.py:execute():144] 500 response executing GraphQL.
2021-11-09 23:08:21,135 ERROR   Thread-4  :1136803 [internal_api.py:execute():145] {"error":"Error 1040: Too many connections"}

2021-11-09 23:08:30,125 ERROR   Thread-4  :1136803 [internal_api.py:execute():144] 500 response executing GraphQL.
2021-11-09 23:08:30,125 ERROR   Thread-4  :1136803 [internal_api.py:execute():145] {"error":"Error 1040: Too many connections"}

2021-11-09 23:08:46,624 ERROR   Thread-4  :1136803 [internal_api.py:execute():144] 500 response executing GraphQL.
2021-11-09 23:08:46,624 ERROR   Thread-4  :1136803 [internal_api.py:execute():145] {"error":"Error 1040: Too many connections"}

2021-11-09 23:08:47,260 INFO    MainThread:1136803 [interface.py:_communicate_run():903] couldn't get run from backend
2021-11-09 23:08:47,260 ERROR   MainThread:1136803 [wandb_init.py:init():553] backend process timed out
2021-11-09 23:08:47,260 ERROR   MainThread:1136803 [wandb_init.py:init():562] encountered error: Error communicating with wandb process
try: wandb.init(settings=wandb.Settings(start_method='fork'))
or:  wandb.init(settings=wandb.Settings(start_method='thread'))
For more info see: https://docs.wandb.ai/library/init#init-start-error
2021-11-09 23:08:53,787 WARNING MainThread:1136803 [wandb_init.py:init():891] interrupted
Traceback (most recent call last):
  File "/media/indika/Sync/anaconda3/lib/python3.8/site-packages/wandb/sdk/wandb_init.py", line 870, in init
    run = wi.init()
  File "/media/indika/Sync/anaconda3/lib/python3.8/site-packages/wandb/sdk/wandb_init.py", line 566, in init
    backend.cleanup()
  File "/media/indika/Sync/anaconda3/lib/python3.8/site-packages/wandb/sdk/backend/backend.py", line 229, in cleanup
    self.wandb_process.join()
  File "/media/indika/Sync/anaconda3/lib/python3.8/multiprocessing/process.py", line 149, in join
    res = self._popen.wait(timeout)
  File "/media/indika/Sync/anaconda3/lib/python3.8/multiprocessing/popen_fork.py", line 47, in wait
    return self.poll(os.WNOHANG if timeout == 0.0 else 0)
  File "/media/indika/Sync/anaconda3/lib/python3.8/multiprocessing/popen_fork.py", line 27, in poll
    pid, sts = os.waitpid(self.pid, flag)
KeyboardInterrupt
