2021-11-09 23:07:43,834 INFO    MainThread:1136430 [internal.py:wandb_internal():88] W&B internal server running at pid: 1136430, started at: 2021-11-09 23:07:43.834624
2021-11-09 23:07:43,836 DEBUG   HandlerThread:1136430 [handler.py:handle_request():130] handle_request: check_version
2021-11-09 23:07:43,836 INFO    WriterThread:1136430 [datastore.py:open_for_write():77] open: /media/indika/Sync/Programming/Projects/Python/Artifical-Intelligence/PyTorch/RNN/Gooogle-Stock-Price-V6/wandb/run-20211109_230742-3ckrxty7/run-3ckrxty7.wandb
2021-11-09 23:07:43,837 DEBUG   SenderThread:1136430 [sender.py:send():185] send: header
2021-11-09 23:07:43,837 DEBUG   SenderThread:1136430 [sender.py:send_request():199] send_request: check_version
2021-11-09 23:07:44,195 DEBUG   SenderThread:1136430 [sender.py:send():185] send: run
2021-11-09 23:07:44,640 ERROR   SenderThread:1136430 [internal_api.py:execute():144] 500 response executing GraphQL.
2021-11-09 23:07:44,640 ERROR   SenderThread:1136430 [internal_api.py:execute():145] {"error":"Error 1040: Too many connections"}

2021-11-09 23:07:46,374 ERROR   SenderThread:1136430 [internal_api.py:execute():144] 500 response executing GraphQL.
2021-11-09 23:07:46,374 ERROR   SenderThread:1136430 [internal_api.py:execute():145] {"error":"Error 1040: Too many connections"}

2021-11-09 23:07:59,001 ERROR   SenderThread:1136430 [retry.py:__call__():126] Retry attempt failed:
Traceback (most recent call last):
  File "/home/indika/.local/lib/python3.8/site-packages/urllib3/connectionpool.py", line 445, in _make_request
    six.raise_from(e, None)
  File "<string>", line 3, in raise_from
  File "/home/indika/.local/lib/python3.8/site-packages/urllib3/connectionpool.py", line 440, in _make_request
    httplib_response = conn.getresponse()
  File "/media/indika/Sync/anaconda3/lib/python3.8/http/client.py", line 1347, in getresponse
    response.begin()
  File "/media/indika/Sync/anaconda3/lib/python3.8/http/client.py", line 307, in begin
    version, status, reason = self._read_status()
  File "/media/indika/Sync/anaconda3/lib/python3.8/http/client.py", line 268, in _read_status
    line = str(self.fp.readline(_MAXLINE + 1), "iso-8859-1")
  File "/media/indika/Sync/anaconda3/lib/python3.8/socket.py", line 669, in readinto
    return self._sock.recv_into(b)
  File "/media/indika/Sync/anaconda3/lib/python3.8/ssl.py", line 1241, in recv_into
    return self.read(nbytes, buffer)
  File "/media/indika/Sync/anaconda3/lib/python3.8/ssl.py", line 1099, in read
    return self._sslobj.read(len, buffer)
socket.timeout: The read operation timed out

During handling of the above exception, another exception occurred:

Traceback (most recent call last):
  File "/home/indika/.local/lib/python3.8/site-packages/requests/adapters.py", line 439, in send
    resp = conn.urlopen(
  File "/home/indika/.local/lib/python3.8/site-packages/urllib3/connectionpool.py", line 755, in urlopen
    retries = retries.increment(
  File "/home/indika/.local/lib/python3.8/site-packages/urllib3/util/retry.py", line 532, in increment
    raise six.reraise(type(error), error, _stacktrace)
  File "/home/indika/.local/lib/python3.8/site-packages/urllib3/packages/six.py", line 770, in reraise
    raise value
  File "/home/indika/.local/lib/python3.8/site-packages/urllib3/connectionpool.py", line 699, in urlopen
    httplib_response = self._make_request(
  File "/home/indika/.local/lib/python3.8/site-packages/urllib3/connectionpool.py", line 447, in _make_request
    self._raise_timeout(err=e, url=url, timeout_value=read_timeout)
  File "/home/indika/.local/lib/python3.8/site-packages/urllib3/connectionpool.py", line 336, in _raise_timeout
    raise ReadTimeoutError(
urllib3.exceptions.ReadTimeoutError: HTTPSConnectionPool(host='api.wandb.ai', port=443): Read timed out. (read timeout=10)

During handling of the above exception, another exception occurred:

Traceback (most recent call last):
  File "/media/indika/Sync/anaconda3/lib/python3.8/site-packages/wandb/sdk/lib/retry.py", line 102, in __call__
    result = self._call_fn(*args, **kwargs)
  File "/media/indika/Sync/anaconda3/lib/python3.8/site-packages/wandb/sdk/internal/internal_api.py", line 141, in execute
    return self.client.execute(*args, **kwargs)
  File "/media/indika/Sync/anaconda3/lib/python3.8/site-packages/wandb/vendor/gql-0.2.0/gql/client.py", line 52, in execute
    result = self._get_result(document, *args, **kwargs)
  File "/media/indika/Sync/anaconda3/lib/python3.8/site-packages/wandb/vendor/gql-0.2.0/gql/client.py", line 60, in _get_result
    return self.transport.execute(document, *args, **kwargs)
  File "/media/indika/Sync/anaconda3/lib/python3.8/site-packages/wandb/vendor/gql-0.2.0/gql/transport/requests.py", line 38, in execute
    request = requests.post(self.url, **post_args)
  File "/home/indika/.local/lib/python3.8/site-packages/requests/api.py", line 117, in post
    return request('post', url, data=data, json=json, **kwargs)
  File "/home/indika/.local/lib/python3.8/site-packages/requests/api.py", line 61, in request
    return session.request(method=method, url=url, **kwargs)
  File "/home/indika/.local/lib/python3.8/site-packages/requests/sessions.py", line 542, in request
    resp = self.send(prep, **send_kwargs)
  File "/home/indika/.local/lib/python3.8/site-packages/requests/sessions.py", line 655, in send
    r = adapter.send(request, **kwargs)
  File "/home/indika/.local/lib/python3.8/site-packages/requests/adapters.py", line 529, in send
    raise ReadTimeout(e, request=request)
requests.exceptions.ReadTimeout: HTTPSConnectionPool(host='api.wandb.ai', port=443): Read timed out. (read timeout=10)
2021-11-09 23:08:04,294 ERROR   SenderThread:1136430 [internal_api.py:execute():144] 500 response executing GraphQL.
2021-11-09 23:08:04,294 ERROR   SenderThread:1136430 [internal_api.py:execute():145] {"error":"Error 1040: Too many connections"}

2021-11-09 23:08:04,327 WARNING MainThread:1136430 [internal.py:wandb_internal():147] Internal process interrupt: 1
2021-11-09 23:08:09,337 WARNING MainThread:1136430 [internal.py:is_dead():367] Internal process exiting, parent pid 1123402 disappeared
2021-11-09 23:08:09,337 ERROR   MainThread:1136430 [internal.py:wandb_internal():143] Internal process shutdown.
2021-11-09 23:08:10,198 INFO    WriterThread:1136430 [datastore.py:close():281] close: /media/indika/Sync/Programming/Projects/Python/Artifical-Intelligence/PyTorch/RNN/Gooogle-Stock-Price-V6/wandb/run-20211109_230742-3ckrxty7/run-3ckrxty7.wandb
2021-11-09 23:08:10,221 INFO    HandlerThread:1136430 [handler.py:finish():731] shutting down handler
2021-11-09 23:08:14,725 ERROR   SenderThread:1136430 [internal_api.py:execute():144] 500 response executing GraphQL.
2021-11-09 23:08:14,725 ERROR   SenderThread:1136430 [internal_api.py:execute():145] {"error":"Error 1040: Too many connections"}

